<?xml version="1.0" encoding="utf-8"?>
<!-- This URDF was automatically created by SolidWorks to URDF Exporter! Originally created by Stephen Brawner (brawner@gmail.com) 
     Commit Version: 1.6.0-4-g7f85cfe  Build Version: 1.6.7995.38578
     For more information, please see http://wiki.ros.org/sw_urdf_exporter -->
<robot
  name="PrimeChair">
  <link
    name="base_link">
    <inertial>
      <origin
        xyz="-0.192036444194214 -9.55948096237336E-08 0.0914570973778513"
        rpy="0 0 0" />
      <mass
        value="157.597764258322" />
      <inertia
        ixx="6.37361221695308"
        ixy="-1.82329745952805E-06"
        ixz="2.88880190579742"
        iyy="22.9341950778055"
        iyz="2.24724981951229E-06"
        izz="25.4220678682299" />
    </inertial>
    <visual>
      <origin
        xyz="0 0 0"
        rpy="0 0 0" />
      <geometry>
        <mesh
          filename="package://PrimeChair/meshes/base_link.STL" />
      </geometry>
      <material
        name="">
        <color
          rgba="0.698039215686274 0.698039215686274 0.698039215686274 1" />
      </material>
    </visual>
    <collision>
      <origin
        xyz="0 0 0"
        rpy="0 0 0" />
      <geometry>
        <mesh
          filename="package://PrimeChair/meshes/base_link.STL" />
      </geometry>
    </collision>
  </link>
  <link
    name="LF">
    <inertial>
      <origin
        xyz="0 0 0.0375000000000001"
        rpy="0 0 0" />
      <mass
        value="6.32107714591448" />
      <inertia
        ixx="0.048351894425708"
        ixy="6.33495941251491E-19"
        ixz="8.44661255001988E-20"
        iyy="0.048351894425708"
        iyz="-4.22330627500996E-20"
        izz="0.0907777790271211" />
    </inertial>
    <visual>
      <origin
        xyz="0 0 0"
        rpy="0 0 0" />
      <geometry>
        <mesh
          filename="package://PrimeChair/meshes/LF.STL" />
      </geometry>
      <material
        name="">
        <color
          rgba="0.298039215686275 0.298039215686275 0.298039215686275 1" />
      </material>
    </visual>
    <collision>
      <origin
        xyz="0 0 0"
        rpy="0 0 0" />
      <geometry>
        <mesh
          filename="package://PrimeChair/meshes/LF.STL" />
      </geometry>
    </collision>
  </link>
  <joint
    name="LF_J"
    type="continuous">
    <origin
      xyz="0.5215 0.257 -0.065"
      rpy="-1.5707963267949 0 0" />
    <parent
      link="base_link" />
    <child
      link="LF" />
    <axis
      xyz="0 0 1" />
  </joint>
  <link
    name="LB">
    <inertial>
      <origin
        xyz="0 0 0.0375"
        rpy="0 0 0" />
      <mass
        value="6.32107714591448" />
      <inertia
        ixx="0.048351894425708"
        ixy="-2.06942007475487E-18"
        ixz="8.44661255001988E-20"
        iyy="0.048351894425708"
        iyz="-4.22330627500996E-20"
        izz="0.0907777790271211" />
    </inertial>
    <visual>
      <origin
        xyz="0 0 0"
        rpy="0 0 0" />
      <geometry>
        <mesh
          filename="package://PrimeChair/meshes/LB.STL" />
      </geometry>
      <material
        name="">
        <color
          rgba="0.298039215686275 0.298039215686275 0.298039215686275 1" />
      </material>
    </visual>
    <collision>
      <origin
        xyz="0 0 0"
        rpy="0 0 0" />
      <geometry>
        <mesh
          filename="package://PrimeChair/meshes/LB.STL" />
      </geometry>
    </collision>
  </link>
  <joint
    name="LB_J"
    type="continuous">
    <origin
      xyz="-0.5215 0.257 -0.0650000000000002"
      rpy="-1.5707963267949 0 0" />
    <parent
      link="base_link" />
    <child
      link="LB" />
    <axis
      xyz="0 0 1" />
  </joint>
  <link
    name="RF">
    <inertial>
      <origin
        xyz="0 1.38777878078145E-17 0.0375000000000001"
        rpy="0 0 0" />
      <mass
        value="6.32107714591448" />
      <inertia
        ixx="0.048351894425708"
        ixy="-1.45368476252277E-35"
        ixz="8.4466125500198E-20"
        iyy="0.048351894425708"
        iyz="-9.68935227477129E-35"
        izz="0.0907777790271211" />
    </inertial>
    <visual>
      <origin
        xyz="0 0 0"
        rpy="0 0 0" />
      <geometry>
        <mesh
          filename="package://PrimeChair/meshes/RF.STL" />
      </geometry>
      <material
        name="">
        <color
          rgba="0.298039215686275 0.298039215686275 0.298039215686275 1" />
      </material>
    </visual>
    <collision>
      <origin
        xyz="0 0 0"
        rpy="0 0 0" />
      <geometry>
        <mesh
          filename="package://PrimeChair/meshes/RF.STL" />
      </geometry>
    </collision>
  </link>
  <joint
    name="RF_J"
    type="continuous">
    <origin
      xyz="0.5215 -0.257 -0.065"
      rpy="1.5707963267949 0 0" />
    <parent
      link="base_link" />
    <child
      link="RF" />
    <axis
      xyz="0 0 1" />
  </joint>
  <link
    name="RB">
    <inertial>
      <origin
        xyz="0 0 0.0374999999999999"
        rpy="0 0 0" />
      <mass
        value="6.32107714591448" />
      <inertia
        ixx="0.048351894425708"
        ixy="5.42694856338777E-18"
        ixz="8.40794326924682E-18"
        iyy="0.0483518944257079"
        iyz="-7.88890775573904E-18"
        izz="0.0907777790271211" />
    </inertial>
    <visual>
      <origin
        xyz="0 0 0"
        rpy="0 0 0" />
      <geometry>
        <mesh
          filename="package://PrimeChair/meshes/RB.STL" />
      </geometry>
      <material
        name="">
        <color
          rgba="0.298039215686275 0.298039215686275 0.298039215686275 1" />
      </material>
    </visual>
    <collision>
      <origin
        xyz="0 0 0"
        rpy="0 0 0" />
      <geometry>
        <mesh
          filename="package://PrimeChair/meshes/RB.STL" />
      </geometry>
    </collision>
  </link>
  <joint
    name="RB_J"
    type="continuous">
    <origin
      xyz="-0.5215 -0.257 -0.0649999999999998"
      rpy="1.5707963267949 0 0" />
    <parent
      link="base_link" />
    <child
      link="RB" />
    <axis
      xyz="0 0 1" />
  </joint>
  <link
    name="NLF">
    <inertial>
      <origin
        xyz="0.00271571168468021 0.278470313824689 0.0242251960106987"
        rpy="0 0 0" />
      <mass
        value="3.73195794065969" />
      <inertia
        ixx="0.0978648811507753"
        ixy="-0.000889029991198783"
        ixz="4.65547571680366E-05"
        iyy="0.0067120107218082"
        iyz="0.00477374601720348"
        izz="0.099425765381797" />
    </inertial>
    <visual>
      <origin
        xyz="0 0 0"
        rpy="0 0 0" />
      <geometry>
        <mesh
          filename="package://PrimeChair/meshes/NLF.STL" />
      </geometry>
      <material
        name="">
        <color
          rgba="0.792156862745098 0.819607843137255 0.933333333333333 1" />
      </material>
    </visual>
    <collision>
      <origin
        xyz="0 0 0"
        rpy="0 0 0" />
      <geometry>
        <mesh
          filename="package://PrimeChair/meshes/NLF.STL" />
      </geometry>
    </collision>
  </link>
  <joint
    name="NLF_J"
    type="continuous">
    <origin
      xyz="0.5215 0.332 -0.065"
      rpy="1.5707963267949 0 3.14159265358979" />
    <parent
      link="base_link" />
    <child
      link="NLF" />
    <axis
      xyz="0 0 1" />
  </joint>
  <link
    name="SLF">
    <inertial>
      <origin
        xyz="1.11022302462516E-16 0 0.04"
        rpy="0 0 0" />
      <mass
        value="2.51603872440699" />
      <inertia
        ixx="0.00917997695589261"
        ixy="-1.4403692952685E-36"
        ixz="2.89120579329467E-19"
        iyy="0.00917997695589261"
        iyz="-2.56608446149947E-35"
        izz="0.0156761792724178" />
    </inertial>
    <visual>
      <origin
        xyz="0 0 0"
        rpy="0 0 0" />
      <geometry>
        <mesh
          filename="package://PrimeChair/meshes/SLF.STL" />
      </geometry>
      <material
        name="">
        <color
          rgba="0.298039215686275 0.298039215686275 0.298039215686275 1" />
      </material>
    </visual>
    <collision>
      <origin
        xyz="0 0 0"
        rpy="0 0 0" />
      <geometry>
        <mesh
          filename="package://PrimeChair/meshes/SLF.STL" />
      </geometry>
    </collision>
  </link>
  <joint
    name="SLF_J"
    type="continuous">
    <origin
      xyz="0.00487589236332042 0.499976225108416 0"
      rpy="3.14159265358979 0 3.14159265358979" />
    <parent
      link="NLF" />
    <child
      link="SLF" />
    <axis
      xyz="0 0 1" />
  </joint>
  <link
    name="NLB">
    <inertial>
      <origin
        xyz="0.00135737071007547 0.278480247623293 0.0242251960106988"
        rpy="0 0 0" />
      <mass
        value="3.73195794065969" />
      <inertia
        ixx="0.0978713852303183"
        ixy="-0.000444372031492282"
        ixz="2.32690620845553E-05"
        iyy="0.00670550664226537"
        iyz="0.00477391630979543"
        izz="0.0994257653817971" />
    </inertial>
    <visual>
      <origin
        xyz="0 0 0"
        rpy="0 0 0" />
      <geometry>
        <mesh
          filename="package://PrimeChair/meshes/NLB.STL" />
      </geometry>
      <material
        name="">
        <color
          rgba="0.792156862745098 0.819607843137255 0.933333333333333 1" />
      </material>
    </visual>
    <collision>
      <origin
        xyz="0 0 0"
        rpy="0 0 0" />
      <geometry>
        <mesh
          filename="package://PrimeChair/meshes/NLB.STL" />
      </geometry>
    </collision>
  </link>
  <joint
    name="NLB_J"
    type="continuous">
    <origin
      xyz="-0.5215 0.332 -0.0650000000000002"
      rpy="1.5707963267949 0 3.14159265358979" />
    <parent
      link="base_link" />
    <child
      link="NLB" />
    <axis
      xyz="0 0 1" />
  </joint>
  <link
    name="SLB">
    <inertial>
      <origin
        xyz="0 -5.55111512312578E-17 0.04"
        rpy="0 0 0" />
      <mass
        value="2.51603872440699" />
      <inertia
        ixx="0.00917997695589261"
        ixy="-1.4403692952685E-36"
        ixz="2.89120579329467E-19"
        iyy="0.00917997695589261"
        iyz="-2.56608446149947E-35"
        izz="0.0156761792724178" />
    </inertial>
    <visual>
      <origin
        xyz="0 0 0"
        rpy="0 0 0" />
      <geometry>
        <mesh
          filename="package://PrimeChair/meshes/SLB.STL" />
      </geometry>
      <material
        name="">
        <color
          rgba="0.298039215686275 0.298039215686275 0.298039215686275 1" />
      </material>
    </visual>
    <collision>
      <origin
        xyz="0 0 0"
        rpy="0 0 0" />
      <geometry>
        <mesh
          filename="package://PrimeChair/meshes/SLB.STL" />
      </geometry>
    </collision>
  </link>
  <joint
    name="SLB_J"
    type="continuous">
    <origin
      xyz="0.00243707515668445 0.499994060629405 0"
      rpy="3.14159265358979 0 3.14159265358979" />
    <parent
      link="NLB" />
    <child
      link="SLB" />
    <axis
      xyz="0 0 1" />
  </joint>
  <link
    name="NRF">
    <inertial>
      <origin
        xyz="0 0.278483555657377 0.0242251960106987"
        rpy="0 0 0" />
      <mass
        value="3.73195794065969" />
      <inertia
        ixx="0.0978735511921236"
        ixy="1.82511641073461E-18"
        ixz="4.94720732004158E-19"
        iyy="0.00670334068045991"
        iyz="0.00477397301858538"
        izz="0.099425765381797" />
    </inertial>
    <visual>
      <origin
        xyz="0 0 0"
        rpy="0 0 0" />
      <geometry>
        <mesh
          filename="package://PrimeChair/meshes/NRF.STL" />
      </geometry>
      <material
        name="">
        <color
          rgba="0.792156862745098 0.819607843137255 0.933333333333333 1" />
      </material>
    </visual>
    <collision>
      <origin
        xyz="0 0 0"
        rpy="0 0 0" />
      <geometry>
        <mesh
          filename="package://PrimeChair/meshes/NRF.STL" />
      </geometry>
    </collision>
  </link>
  <joint
    name="NRF_J"
    type="continuous">
    <origin
      xyz="0.5215 -0.332 -0.065"
      rpy="1.5707963267949 0 0" />
    <parent
      link="base_link" />
    <child
      link="NRF" />
    <axis
      xyz="0 0 1" />
  </joint>
  <link
    name="SRF">
    <inertial>
      <origin
        xyz="0 -5.55111512312578E-17 0.04"
        rpy="0 0 0" />
      <mass
        value="2.516038724407" />
      <inertia
        ixx="0.00917997695589263"
        ixy="-1.23949154614879E-18"
        ixz="2.89120579329468E-19"
        iyy="0.00917997695589263"
        iyz="-5.42101086242753E-20"
        izz="0.0156761792724178" />
    </inertial>
    <visual>
      <origin
        xyz="0 0 0"
        rpy="0 0 0" />
      <geometry>
        <mesh
          filename="package://PrimeChair/meshes/SRF.STL" />
      </geometry>
      <material
        name="">
        <color
          rgba="0.298039215686275 0.298039215686275 0.298039215686275 1" />
      </material>
    </visual>
    <collision>
      <origin
        xyz="0 0 0"
        rpy="0 0 0" />
      <geometry>
        <mesh
          filename="package://PrimeChair/meshes/SRF.STL" />
      </geometry>
    </collision>
  </link>
  <joint
    name="SRF_J"
    type="continuous">
    <origin
      xyz="0 0.5 0"
      rpy="3.14159265358979 0 3.14159265358979" />
    <parent
      link="NRF" />
    <child
      link="SRF" />
    <axis
      xyz="0 0 1" />
  </joint>
  <link
    name="NRB">
    <inertial>
      <origin
        xyz="0 0.278483555657377 0.0242251960106987"
        rpy="0 0 0" />
      <mass
        value="3.73195794065969" />
      <inertia
        ixx="0.0978735511921237"
        ixy="-1.46394839361544E-18"
        ixz="8.57883002614217E-19"
        iyy="0.00670334068045991"
        iyz="0.00477397301858539"
        izz="0.099425765381797" />
    </inertial>
    <visual>
      <origin
        xyz="0 0 0"
        rpy="0 0 0" />
      <geometry>
        <mesh
          filename="package://PrimeChair/meshes/NRB.STL" />
      </geometry>
      <material
        name="">
        <color
          rgba="0.792156862745098 0.819607843137255 0.933333333333333 1" />
      </material>
    </visual>
    <collision>
      <origin
        xyz="0 0 0"
        rpy="0 0 0" />
      <geometry>
        <mesh
          filename="package://PrimeChair/meshes/NRB.STL" />
      </geometry>
    </collision>
  </link>
  <joint
    name="NRB_J"
    type="continuous">
    <origin
      xyz="-0.5215 -0.332 -0.065"
      rpy="1.5707963267949 0 0" />
    <parent
      link="base_link" />
    <child
      link="NRB" />
    <axis
      xyz="0 0 1" />
  </joint>
  <link
    name="SRB">
    <inertial>
      <origin
        xyz="0 -5.55111512312578E-17 0.04"
        rpy="0 0 0" />
      <mass
        value="2.516038724407" />
      <inertia
        ixx="0.00917997695589263"
        ixy="-1.23949154614879E-18"
        ixz="-2.89120579329468E-19"
        iyy="0.00917997695589263"
        iyz="9.03501810404587E-20"
        izz="0.0156761792724178" />
    </inertial>
    <visual>
      <origin
        xyz="0 0 0"
        rpy="0 0 0" />
      <geometry>
        <mesh
          filename="package://PrimeChair/meshes/SRB.STL" />
      </geometry>
      <material
        name="">
        <color
          rgba="0.298039215686275 0.298039215686275 0.298039215686275 1" />
      </material>
    </visual>
    <collision>
      <origin
        xyz="0 0 0"
        rpy="0 0 0" />
      <geometry>
        <mesh
          filename="package://PrimeChair/meshes/SRB.STL" />
      </geometry>
    </collision>
  </link>
  <joint
    name="SRB_J"
    type="continuous">
    <origin
      xyz="0 0.5 0"
      rpy="3.14159265358979 0 3.14159265358979" />
    <parent
      link="NRB" />
    <child
      link="SRB" />
    <axis
      xyz="0 0 1" />
  </joint>
</robot>